<sdf version='1.6'>
  <world name='default'>
    <light name='sun' type='directional'>
      <cast_shadows>1</cast_shadows>
      <pose frame=''>0 0 10 0 -0 0</pose>
      <diffuse>0.8 0.8 0.8 1</diffuse>
      <specular>0.2 0.2 0.2 1</specular>
      <attenuation>
        <range>1000</range>
        <constant>0.9</constant>
        <linear>0.01</linear>
        <quadratic>0.001</quadratic>
      </attenuation>
      <direction>-0.5 0.1 -0.9</direction>
    </light>
    <model name='ground_plane'>
      <static>1</static>
      <link name='link'>
        <collision name='collision'>
          <geometry>
            <plane>
              <normal>0 0 1</normal>
              <size>100 100</size>
            </plane>
          </geometry>
          <surface>
            <friction>
              <ode>
                <mu>100</mu>
                <mu2>50</mu2>
              </ode>
              <torsional>
                <ode/>
              </torsional>
            </friction>
            <contact>
              <ode/>
            </contact>
            <bounce/>
          </surface>
          <max_contacts>10</max_contacts>
        </collision>
        <visual name='visual'>
          <cast_shadows>0</cast_shadows>
          <geometry>
            <plane>
              <normal>0 0 1</normal>
              <size>100 100</size>
            </plane>
          </geometry>
          <material>
            <script>
              <uri>file://media/materials/scripts/gazebo.material</uri>
              <name>Gazebo/Grey</name>
            </script>
          </material>
        </visual>
        <self_collide>0</self_collide>
        <enable_wind>0</enable_wind>
        <kinematic>0</kinematic>
      </link>
    </model>
    <gravity>0 0 -9.8</gravity>
    <magnetic_field>6e-06 2.3e-05 -4.2e-05</magnetic_field>
    <atmosphere type='adiabatic'/>
    <physics name='default_physics' default='0' type='ode'>
      <max_step_size>0.001</max_step_size>
      <real_time_factor>1</real_time_factor>
      <real_time_update_rate>1000</real_time_update_rate>
    </physics>
    <scene>
      <ambient>0.4 0.4 0.4 1</ambient>
      <background>0.7 0.7 0.7 1</background>
      <shadows>1</shadows>
    </scene>
    <audio>
      <device>default</device>
    </audio>
    <wind/>
    <spherical_coordinates>
      <surface_model>EARTH_WGS84</surface_model>
      <latitude_deg>0</latitude_deg>
      <longitude_deg>0</longitude_deg>
      <elevation>0</elevation>
      <heading_deg>0</heading_deg>
    </spherical_coordinates>
    <model name='mars_lite'>
      <link name='base_link'>
        <pose frame=''>0 0 0 0 -0 0</pose>
        <inertial>
          <pose frame=''>-0.00698 -0 0.237346 0 -0 0</pose>
          <mass>89.54</mass>
          <inertia>
            <ixx>3.07565</ixx>
            <ixy>1.93737e-19</ixy>
            <ixz>0.154783</ixz>
            <iyy>4.15018</iyy>
            <iyz>-4.82211e-17</iyz>
            <izz>3.70105</izz>
          </inertia>
        </inertial>
        <collision name='base_link_collision'>
          <pose frame=''>0 0 0.235 0 -0 0</pose>
          <geometry>
            <box>
              <size>0.63 0.51 0.29</size>
            </box>
          </geometry>
          <surface>
            <contact>
              <ode>
                <kp>1e+06</kp>
                <kd>10000</kd>
              </ode>
            </contact>
            <friction>
              <ode>
                <mu>0.01</mu>
                <mu2>0.01</mu2>
                <fdir1>1 0 0</fdir1>
              </ode>
              <torsional>
                <ode/>
              </torsional>
            </friction>
            <bounce/>
          </surface>
          <max_contacts>10</max_contacts>
        </collision>
        <collision name='base_link_fixed_joint_lump__back_laser_frame_collision_1'>
          <pose frame=''>-0.285 0 0.0615 -3.14159 -0 -3.14159</pose>
          <geometry>
            <box>
              <size>0.058 0.058 0.087</size>
            </box>
          </geometry>
          <surface>
            <contact>
              <ode/>
            </contact>
            <friction>
              <ode/>
              <torsional>
                <ode/>
              </torsional>
            </friction>
            <bounce/>
          </surface>
          <max_contacts>10</max_contacts>
        </collision>
        <collision name='base_link_fixed_joint_lump__back_left_caster_support_collision_2'>
          <pose frame=''>-0.225 0.17 0 0 -0 0</pose>
          <geometry>
            <cylinder>
              <length>0.2032</length>
              <radius>0.025</radius>
            </cylinder>
          </geometry>
          <surface>
            <contact>
              <ode>
                <kp>1e+06</kp>
                <kd>10000</kd>
              </ode>
            </contact>
            <friction>
              <ode>
                <mu>0.01</mu>
                <mu2>0.01</mu2>
                <fdir1>1 0 0</fdir1>
              </ode>
              <torsional>
                <ode/>
              </torsional>
            </friction>
            <bounce/>
          </surface>
          <max_contacts>10</max_contacts>
        </collision>
        <collision name='base_link_fixed_joint_lump__back_right_caster_support_collision_3'>
          <pose frame=''>-0.225 -0.17 0 0 -0 0</pose>
          <geometry>
            <cylinder>
              <length>0.2032</length>
              <radius>0.025</radius>
            </cylinder>
          </geometry>
          <surface>
            <contact>
              <ode>
                <kp>1e+06</kp>
                <kd>10000</kd>
              </ode>
            </contact>
            <friction>
              <ode>
                <mu>0.01</mu>
                <mu2>0.01</mu2>
                <fdir1>1 0 0</fdir1>
              </ode>
              <torsional>
                <ode/>
              </torsional>
            </friction>
            <bounce/>
          </surface>
          <max_contacts>10</max_contacts>
        </collision>
        <collision name='base_link_fixed_joint_lump__tm_cntrl_box_collision_4'>
          <pose frame=''>-0.125 0 0.485 0 -0 0</pose>
          <geometry>
            <box>
              <size>0.29 0.43 0.23</size>
            </box>
          </geometry>
          <max_contacts>10</max_contacts>
          <surface>
            <contact>
              <ode/>
            </contact>
            <bounce/>
            <friction>
              <torsional>
                <ode/>
              </torsional>
              <ode/>
            </friction>
          </surface>
        </collision>
        <collision name='base_link_fixed_joint_lump__front_laser_frame_collision_5'>
          <pose frame=''>0.285 0 0.0615 3.14159 -0 0</pose>
          <geometry>
            <box>
              <size>0.058 0.058 0.087</size>
            </box>
          </geometry>
          <surface>
            <contact>
              <ode/>
            </contact>
            <friction>
              <ode/>
              <torsional>
                <ode/>
              </torsional>
            </friction>
            <bounce/>
          </surface>
          <max_contacts>10</max_contacts>
        </collision>
        <collision name='base_link_fixed_joint_lump__front_left_caster_support_collision_6'>
          <pose frame=''>0.225 0.17 0 0 -0 0</pose>
          <geometry>
            <cylinder>
              <length>0.2032</length>
              <radius>0.025</radius>
            </cylinder>
          </geometry>
          <surface>
            <contact>
              <ode>
                <kp>1e+06</kp>
                <kd>10000</kd>
              </ode>
            </contact>
            <friction>
              <ode>
                <mu>0.01</mu>
                <mu2>0.01</mu2>
                <fdir1>1 0 0</fdir1>
              </ode>
              <torsional>
                <ode/>
              </torsional>
            </friction>
            <bounce/>
          </surface>
          <max_contacts>10</max_contacts>
        </collision>
        <collision name='base_link_fixed_joint_lump__front_right_caster_support_collision_7'>
          <pose frame=''>0.225 -0.17 0 0 -0 0</pose>
          <geometry>
            <cylinder>
              <length>0.2032</length>
              <radius>0.025</radius>
            </cylinder>
          </geometry>
          <surface>
            <contact>
              <ode>
                <kp>1e+06</kp>
                <kd>10000</kd>
              </ode>
            </contact>
            <friction>
              <ode>
                <mu>0.01</mu>
                <mu2>0.01</mu2>
                <fdir1>1 0 0</fdir1>
              </ode>
              <torsional>
                <ode/>
              </torsional>
            </friction>
            <bounce/>
          </surface>
          <max_contacts>10</max_contacts>
        </collision>
        <visual name='base_link_visual'>
          <pose frame=''>0 0 0 0 -0 0</pose>
          <geometry>
            <mesh>
              <scale>1 1 1</scale>
              <uri>/home/sis/sis2021_final/catkin_ws/src/marslite/mars_lite_description/meshes/mob_plat.dae</uri>
            </mesh>
          </geometry>
          <material>
            <script>
              <uri>__default__</uri>
              <name>__default__</name>
            </script>
          </material>
        </visual>
        <visual name='base_link_fixed_joint_lump__back_laser_frame_visual_1'>
          <pose frame=''>-0.285 0 0.05 -3.14159 -0 -3.14159</pose>
          <geometry>
            <mesh>
              <scale>1 1 1</scale>
              <uri>/opt/ros/melodic/share/hector_sensors_description/meshes/hokuyo_utm30lx/hokuyo_utm_30lx.dae</uri>
            </mesh>
          </geometry>
          <material>
            <script>
              <uri>__default__</uri>
              <name>__default__</name>
            </script>
          </material>
        </visual>
        <visual name='base_link_fixed_joint_lump__front_laser_frame_visual_2'>
          <pose frame=''>0.285 0 0.05 3.14159 -0 0</pose>
          <geometry>
            <mesh>
              <scale>1 1 1</scale>
              <uri>/opt/ros/melodic/share/hector_sensors_description/meshes/hokuyo_utm30lx/hokuyo_utm_30lx.dae</uri>
            </mesh>
          </geometry>
          <material>
            <script>
              <uri>__default__</uri>
              <name>__default__</name>
            </script>
          </material>
        </visual>
        <velocity_decay/>
        <velocity_decay/>
        <sensor name='back_laser' type='ray'>
          <always_on>1</always_on>
          <update_rate>40</update_rate>
          <visualize>0</visualize>
          <ray>
            <scan>
              <horizontal>
                <samples>1081</samples>
                <resolution>1</resolution>
                <min_angle>-1.5708</min_angle>
                <max_angle>1.5708</max_angle>
              </horizontal>
              <vertical>
                <samples>1</samples>
                <min_angle>0</min_angle>
                <max_angle>0</max_angle>
              </vertical>
            </scan>
            <range>
              <min>0.2</min>
              <max>30</max>
              <resolution>0.01</resolution>
            </range>
            <noise>
              <type>gaussian</type>
              <mean>0</mean>
              <stddev>0.004</stddev>
            </noise>
          </ray>
          <plugin name='gazebo_ros_back_laser_controller' filename='libgazebo_ros_laser.so'>
            <topicName>back_scan</topicName>
            <frameName>back_laser_frame</frameName>
            <robotNamespace>/</robotNamespace>
          </plugin>
          <pose frame=''>-0.285 0 0.05 -3.14159 -0 -3.14159</pose>
        </sensor>
        <velocity_decay/>
        <velocity_decay/>
        <velocity_decay/>
        <sensor name='front_laser' type='ray'>
          <always_on>1</always_on>
          <update_rate>40</update_rate>
          <visualize>0</visualize>
          <ray>
            <scan>
              <horizontal>
                <samples>1081</samples>
                <resolution>1</resolution>
                <min_angle>-1.5708</min_angle>
                <max_angle>1.5708</max_angle>
              </horizontal>
              <vertical>
                <samples>1</samples>
                <min_angle>0</min_angle>
                <max_angle>0</max_angle>
              </vertical>
            </scan>
            <range>
              <min>0.2</min>
              <max>30</max>
              <resolution>0.01</resolution>
            </range>
            <noise>
              <type>gaussian</type>
              <mean>0</mean>
              <stddev>0.004</stddev>
            </noise>
          </ray>
          <plugin name='gazebo_ros_front_laser_controller' filename='libgazebo_ros_laser.so'>
            <topicName>front_scan</topicName>
            <frameName>front_laser_frame</frameName>
            <robotNamespace>/</robotNamespace>
          </plugin>
          <pose frame=''>0.285 0 0.05 3.14159 -0 0</pose>
        </sensor>
        <velocity_decay/>
        <gravity>1</gravity>
        <velocity_decay/>
        <self_collide>0</self_collide>
        <enable_wind>0</enable_wind>
        <kinematic>0</kinematic>
      </link>
      <link name='tm_base'>
        <pose frame=''>0.35 0 0.37 0 -0 0</pose>
        <inertial>
          <pose frame=''>0 0 0 0 -0 0</pose>
          <mass>1</mass>
          <inertia>
            <ixx>0.00110833</ixx>
            <ixy>0</ixy>
            <ixz>0</ixz>
            <iyy>0.00110833</iyy>
            <iyz>3.38681e-15</iyz>
            <izz>0.0018</izz>
          </inertia>
        </inertial>
        <collision name='tm_base_link_collision'>
          <pose frame=''>0 0 0 1.5708 -0 0</pose>
          <geometry>
            <mesh>
              <scale>1 1 1</scale>
              <uri>/home/sis/sis2021_final/catkin_ws/src/marslite/tmr_ros1_simplified_edition/tm5_description/meshes/tm5_900/collision/tm5_base_c.stl</uri>
            </mesh>
          </geometry>
          <surface>
            <contact>
              <ode/>
            </contact>
            <friction>
              <ode/>
              <torsional>
                <ode/>
              </torsional>
            </friction>
            <bounce/>
          </surface>
          <max_contacts>10</max_contacts>
        </collision>
        <visual name='tm_base_link_visual'>
          <pose frame=''>0 0 0 1.5708 -0 0</pose>
          <geometry>
            <mesh>
              <scale>1 1 1</scale>
              <uri>/home/sis/sis2021_final/catkin_ws/src/marslite/tmr_ros1_simplified_edition/tm5_description/meshes/tm5_900/visual/tm5_base.stl</uri>
            </mesh>
          </geometry>
          <material>
            <script>
              <name>Gazebo/Grey</name>
              <uri>file://media/materials/scripts/gazebo.material</uri>
            </script>
          </material>
        </visual>
        <gravity>1</gravity>
        <velocity_decay/>
        <self_collide>1</self_collide>
        <enable_wind>0</enable_wind>
        <kinematic>0</kinematic>
      </link>
      <joint name='base_link_to_tm_base' type='revolute'>
        <child>tm_base</child>
        <parent>base_link</parent>
        <axis>
          <limit>
            <lower>0</lower>
            <upper>0</upper>
          </limit>
          <dynamics>
            <damping>0</damping>
            <friction>0</friction>
            <spring_reference>0</spring_reference>
            <spring_stiffness>0</spring_stiffness>
          </dynamics>
          <use_parent_model_frame>1</use_parent_model_frame>
          <xyz>0 0 1</xyz>
        </axis>
        <physics>
          <ode>
            <limit>
              <cfm>0</cfm>
              <erp>0.2</erp>
            </limit>
          </ode>
        </physics>
      </joint>
      <link name='tm_shoulder_1_link'>
        <pose frame=''>0.35 0 0.5152 1.5708 -0 0</pose>
        <inertial>
          <pose frame=''>0 0 0 0 -0 0</pose>
          <mass>4.5</mass>
          <inertia>
            <ixx>0.0124875</ixx>
            <ixy>0</ixy>
            <ixz>0</ixz>
            <iyy>0.0081</iyy>
            <iyz>0</iyz>
            <izz>0.0124875</izz>
          </inertia>
        </inertial>
        <collision name='tm_shoulder_1_link_collision'>
          <pose frame=''>0 0 0 0 -0 0</pose>
          <geometry>
            <mesh>
              <scale>1 1 1</scale>
              <uri>/home/sis/sis2021_final/catkin_ws/src/marslite/tmr_ros1_simplified_edition/tm5_description/meshes/tm5_900/collision/tm_400w_01_c.stl</uri>
            </mesh>
          </geometry>
          <surface>
            <contact>
              <ode/>
            </contact>
            <friction>
              <ode/>
              <torsional>
                <ode/>
              </torsional>
            </friction>
            <bounce/>
          </surface>
          <max_contacts>10</max_contacts>
        </collision>
        <visual name='tm_shoulder_1_link_visual'>
          <pose frame=''>0 0 0 0 -0 0</pose>
          <geometry>
            <mesh>
              <scale>1 1 1</scale>
              <uri>/home/sis/sis2021_final/catkin_ws/src/marslite/tmr_ros1_simplified_edition/tm5_description/meshes/tm5_900/visual/tm_400w_01.stl</uri>
            </mesh>
          </geometry>
          <material>
            <script>
              <name>Gazebo/DarkGrey</name>
              <uri>file://media/materials/scripts/gazebo.material</uri>
            </script>
          </material>
        </visual>
        <gravity>1</gravity>
        <velocity_decay/>
        <self_collide>1</self_collide>
        <enable_wind>0</enable_wind>
        <kinematic>0</kinematic>
      </link>
      <joint name='tm_shoulder_1_joint' type='revolute'>
        <child>tm_shoulder_1_link</child>
        <parent>tm_base</parent>
        <axis>
          <xyz>0 0 1</xyz>
          <limit>
            <lower>-4.71239</lower>
            <upper>4.71239</upper>
            <effort>150</effort>
            <velocity>3.15</velocity>
          </limit>
          <dynamics>
            <damping>0</damping>
            <friction>0</friction>
            <spring_reference>0</spring_reference>
            <spring_stiffness>0</spring_stiffness>
          </dynamics>
          <use_parent_model_frame>1</use_parent_model_frame>
        </axis>
      </joint>
      <link name='tm_arm_1_link'>
        <pose frame=''>0.35 -0.146 0.5152 1.5708 -0 0</pose>
        <inertial>
          <pose frame=''>0 0.1645 0 0 -0 0</pose>
          <mass>11</mass>
          <inertia>
            <ixx>0.109121</ixx>
            <ixy>0</ixy>
            <ixz>0</ixz>
            <iyy>0.0198</iyy>
            <iyz>0</iyz>
            <izz>0.109121</izz>
          </inertia>
        </inertial>
        <collision name='tm_arm_1_link_collision'>
          <pose frame=''>0 0 0 0 -0 0</pose>
          <geometry>
            <mesh>
              <scale>1 1 1</scale>
              <uri>/home/sis/sis2021_final/catkin_ws/src/marslite/tmr_ros1_simplified_edition/tm5_description/meshes/tm5_700/collision/tm5_700_arm1_c.stl</uri>
            </mesh>
          </geometry>
          <surface>
            <contact>
              <ode/>
            </contact>
            <friction>
              <ode/>
              <torsional>
                <ode/>
              </torsional>
            </friction>
            <bounce/>
          </surface>
          <max_contacts>10</max_contacts>
        </collision>
        <visual name='tm_arm_1_link_visual'>
          <pose frame=''>0 0 0 0 -0 0</pose>
          <geometry>
            <mesh>
              <scale>1 1 1</scale>
              <uri>/home/sis/sis2021_final/catkin_ws/src/marslite/tmr_ros1_simplified_edition/tm5_description/meshes/tm5_700/visual/tm5_700_arm1.stl</uri>
            </mesh>
          </geometry>
          <material>
            <script>
              <name>Gazebo/DarkGrey</name>
              <uri>file://media/materials/scripts/gazebo.material</uri>
            </script>
          </material>
        </visual>
        <gravity>1</gravity>
        <velocity_decay/>
        <self_collide>1</self_collide>
        <enable_wind>0</enable_wind>
        <kinematic>0</kinematic>
      </link>
      <joint name='tm_shoulder_2_joint' type='revolute'>
        <child>tm_arm_1_link</child>
        <parent>tm_shoulder_1_link</parent>
        <axis>
          <xyz>0 1 -0</xyz>
          <limit>
            <lower>-3.14159</lower>
            <upper>3.14159</upper>
            <effort>150</effort>
            <velocity>3.15</velocity>
          </limit>
          <dynamics>
            <damping>0</damping>
            <friction>0</friction>
            <spring_reference>0</spring_reference>
            <spring_stiffness>0</spring_stiffness>
          </dynamics>
          <use_parent_model_frame>1</use_parent_model_frame>
        </axis>
      </joint>
      <link name='tm_arm_2_link'>
        <pose frame=''>0.35 -0.0163 0.8442 1.5708 -0 0</pose>
        <inertial>
          <pose frame=''>0 0.15575 0 0 -0 0</pose>
          <mass>2.5</mass>
          <inertia>
            <ixx>0.0214807</ixx>
            <ixy>0</ixy>
            <ixz>0</ixz>
            <iyy>0.00253125</iyy>
            <iyz>0</iyz>
            <izz>0.0214807</izz>
          </inertia>
        </inertial>
        <collision name='tm_arm_2_link_collision'>
          <pose frame=''>0 0 0 0 -0 0</pose>
          <geometry>
            <mesh>
              <scale>1 1 1</scale>
              <uri>/home/sis/sis2021_final/catkin_ws/src/marslite/tmr_ros1_simplified_edition/tm5_description/meshes/tm5_700/collision/tm5_700_arm2_c.stl</uri>
            </mesh>
          </geometry>
          <surface>
            <contact>
              <ode/>
            </contact>
            <friction>
              <ode/>
              <torsional>
                <ode/>
              </torsional>
            </friction>
            <bounce/>
          </surface>
          <max_contacts>10</max_contacts>
        </collision>
        <visual name='tm_arm_2_link_visual'>
          <pose frame=''>0 0 0 0 -0 0</pose>
          <geometry>
            <mesh>
              <scale>1 1 1</scale>
              <uri>/home/sis/sis2021_final/catkin_ws/src/marslite/tmr_ros1_simplified_edition/tm5_description/meshes/tm5_700/visual/tm5_700_arm2.stl</uri>
            </mesh>
          </geometry>
          <material>
            <script>
              <name>Gazebo/DarkGrey</name>
              <uri>file://media/materials/scripts/gazebo.material</uri>
            </script>
          </material>
        </visual>
        <gravity>1</gravity>
        <velocity_decay/>
        <self_collide>1</self_collide>
        <enable_wind>0</enable_wind>
        <kinematic>0</kinematic>
      </link>
      <joint name='tm_elbow_joint' type='revolute'>
        <child>tm_arm_2_link</child>
        <parent>tm_arm_1_link</parent>
        <axis>
          <xyz>0 1 -0</xyz>
          <limit>
            <lower>-3.14159</lower>
            <upper>3.14159</upper>
            <effort>150</effort>
            <velocity>3.15</velocity>
          </limit>
          <dynamics>
            <damping>0</damping>
            <friction>0</friction>
            <spring_reference>0</spring_reference>
            <spring_stiffness>0</spring_stiffness>
          </dynamics>
          <use_parent_model_frame>1</use_parent_model_frame>
        </axis>
      </joint>
      <link name='tm_wrist_1_link'>
        <pose frame=''>0.35 -0.1223 1.1557 1.5708 -0 0</pose>
        <inertial>
          <pose frame=''>0 0 0 0 -0 0</pose>
          <mass>1.45</mass>
          <inertia>
            <ixx>0.00116906</ixx>
            <ixy>0</ixy>
            <ixz>0</ixz>
            <iyy>0.00146813</iyy>
            <iyz>0</iyz>
            <izz>0.00116906</izz>
          </inertia>
        </inertial>
        <collision name='tm_wrist_1_link_collision'>
          <pose frame=''>0 0 0 0 -0 0</pose>
          <geometry>
            <mesh>
              <scale>1 1 1</scale>
              <uri>/home/sis/sis2021_final/catkin_ws/src/marslite/tmr_ros1_simplified_edition/tm5_description/meshes/tm5_900/collision/tm_100w_01_c.stl</uri>
            </mesh>
          </geometry>
          <surface>
            <contact>
              <ode/>
            </contact>
            <friction>
              <ode/>
              <torsional>
                <ode/>
              </torsional>
            </friction>
            <bounce/>
          </surface>
          <max_contacts>10</max_contacts>
        </collision>
        <visual name='tm_wrist_1_link_visual'>
          <pose frame=''>0 0 0 0 -0 0</pose>
          <geometry>
            <mesh>
              <scale>1 1 1</scale>
              <uri>/home/sis/sis2021_final/catkin_ws/src/marslite/tmr_ros1_simplified_edition/tm5_description/meshes/tm5_900/visual/tm_100w_01.stl</uri>
            </mesh>
          </geometry>
          <material>
            <script>
              <name>Gazebo/DarkGrey</name>
              <uri>file://media/materials/scripts/gazebo.material</uri>
            </script>
          </material>
        </visual>
        <gravity>1</gravity>
        <velocity_decay/>
        <self_collide>1</self_collide>
        <enable_wind>0</enable_wind>
        <kinematic>0</kinematic>
      </link>
      <joint name='tm_wrist_1_joint' type='revolute'>
        <child>tm_wrist_1_link</child>
        <parent>tm_arm_2_link</parent>
        <axis>
          <xyz>0 1 -0</xyz>
          <limit>
            <lower>-3.14159</lower>
            <upper>3.14159</upper>
            <effort>150</effort>
            <velocity>3.15</velocity>
          </limit>
          <dynamics>
            <damping>0</damping>
            <friction>0</friction>
            <spring_reference>0</spring_reference>
            <spring_stiffness>0</spring_stiffness>
          </dynamics>
          <use_parent_model_frame>1</use_parent_model_frame>
        </axis>
      </joint>
      <link name='tm_wrist_2_link'>
        <pose frame=''>0.35 -0.1223 1.2617 1.5708 -0 0</pose>
        <inertial>
          <pose frame=''>0 0 0 0 -0 0</pose>
          <mass>1.45</mass>
          <inertia>
            <ixx>0.00247406</ixx>
            <ixy>0</ixy>
            <ixz>0</ixz>
            <iyy>0.00247406</iyy>
            <iyz>0</iyz>
            <izz>0.00146813</izz>
          </inertia>
        </inertial>
        <collision name='tm_wrist_2_link_collision'>
          <pose frame=''>0 0 0 0 -0 0</pose>
          <geometry>
            <mesh>
              <scale>1 1 1</scale>
              <uri>/home/sis/sis2021_final/catkin_ws/src/marslite/tmr_ros1_simplified_edition/tm5_description/meshes/tm5_900/collision/tm_100w_02_c.stl</uri>
            </mesh>
          </geometry>
          <surface>
            <contact>
              <ode/>
            </contact>
            <friction>
              <ode/>
              <torsional>
                <ode/>
              </torsional>
            </friction>
            <bounce/>
          </surface>
          <max_contacts>10</max_contacts>
        </collision>
        <visual name='tm_wrist_2_link_visual'>
          <pose frame=''>0 0 0 0 -0 0</pose>
          <geometry>
            <mesh>
              <scale>1 1 1</scale>
              <uri>/home/sis/sis2021_final/catkin_ws/src/marslite/tmr_ros1_simplified_edition/tm5_description/meshes/tm5_900/visual/tm_100w_02.stl</uri>
            </mesh>
          </geometry>
          <material>
            <script>
              <name>Gazebo/DarkGrey</name>
              <uri>file://media/materials/scripts/gazebo.material</uri>
            </script>
          </material>
        </visual>
        <gravity>1</gravity>
        <velocity_decay/>
        <self_collide>1</self_collide>
        <enable_wind>0</enable_wind>
        <kinematic>0</kinematic>
      </link>
      <joint name='tm_wrist_2_joint' type='revolute'>
        <child>tm_wrist_2_link</child>
        <parent>tm_wrist_1_link</parent>
        <axis>
          <xyz>0 0 1</xyz>
          <limit>
            <lower>-3.14159</lower>
            <upper>3.14159</upper>
            <effort>150</effort>
            <velocity>3.15</velocity>
          </limit>
          <dynamics>
            <damping>0</damping>
            <friction>0</friction>
            <spring_reference>0</spring_reference>
            <spring_stiffness>0</spring_stiffness>
          </dynamics>
          <use_parent_model_frame>1</use_parent_model_frame>
        </axis>
      </joint>
      <link name='tm_wrist_3_link'>
        <pose frame=''>0.35 -0.23545 1.2617 1.5708 -0 0</pose>
        <inertial>
          <pose frame=''>0 0 0 0 -0 0</pose>
          <mass>1.03695</mass>
          <inertia>
            <ixx>0.0017925</ixx>
            <ixy>-3.73517e-21</ixy>
            <ixz>-2.96577e-36</ixz>
            <iyy>0.0018535</iyy>
            <iyz>4.84348e-20</iyz>
            <izz>0.000785</izz>
          </inertia>
        </inertial>
        <collision name='tm_wrist_3_link_collision'>
          <pose frame=''>0 0 0 0 -0 0</pose>
          <geometry>
            <mesh>
              <scale>1 1 1</scale>
              <uri>/home/sis/sis2021_final/catkin_ws/src/marslite/tmr_ros1_simplified_edition/tm5_description/meshes/tm5_900/collision/tm_ee_c.stl</uri>
            </mesh>
          </geometry>
          <surface>
            <contact>
              <ode/>
            </contact>
            <friction>
              <ode/>
              <torsional>
                <ode/>
              </torsional>
            </friction>
            <bounce/>
          </surface>
          <max_contacts>10</max_contacts>
        </collision>
        <collision name='tm_wrist_3_link_fixed_joint_lump__robotiq_85_base_link_collision_1'>
          <pose frame=''>0 0 0 3.14159 -1.57079 1.57079</pose>
          <geometry>
            <mesh>
              <scale>1 1 1</scale>
              <uri>/home/sis/sis2021_final/catkin_ws/src/marslite/robotiq/robotiq_description/meshes/collision/robotiq_85_base_link.stl</uri>
            </mesh>
          </geometry>
          <max_contacts>10</max_contacts>
          <surface>
            <contact>
              <ode/>
            </contact>
            <bounce/>
            <friction>
              <torsional>
                <ode/>
              </torsional>
              <ode/>
            </friction>
          </surface>
        </collision>
        <visual name='tm_wrist_3_link_visual'>
          <pose frame=''>0 0 0 0 -0 0</pose>
          <geometry>
            <mesh>
              <scale>1 1 1</scale>
              <uri>/home/sis/sis2021_final/catkin_ws/src/marslite/tmr_ros1_simplified_edition/tm5_description/meshes/tm5_900/visual/tm_ee.stl</uri>
            </mesh>
          </geometry>
          <material>
            <script>
              <name>Gazebo/Grey</name>
              <uri>file://media/materials/scripts/gazebo.material</uri>
            </script>
          </material>
        </visual>
        <visual name='tm_wrist_3_link_fixed_joint_lump__camera1_realsense_lens_visual_1'>
          <pose frame=''>-0 0.06 0.0735 0 -0 0</pose>
          <geometry>
            <mesh>
              <scale>1 1 1</scale>
              <uri>/home/sis/sis2021_final/catkin_ws/src/marslite/mars_lite_description/meshes/d415_lite.stl</uri>
            </mesh>
          </geometry>
          <material>
            <script>
              <name>Gazebo/Grey</name>
              <uri>file://media/materials/scripts/gazebo.material</uri>
            </script>
          </material>
        </visual>
        <visual name='tm_wrist_3_link_fixed_joint_lump__robotiq_85_base_link_visual_2'>
          <pose frame=''>0 0 0 3.14159 -1.57079 1.57079</pose>
          <geometry>
            <mesh>
              <scale>1 1 1</scale>
              <uri>/home/sis/sis2021_final/catkin_ws/src/marslite/robotiq/robotiq_description/meshes/visual/robotiq_85_base_link.dae</uri>
            </mesh>
          </geometry>
        </visual>
        <velocity_decay/>
        <self_collide>1</self_collide>
        <velocity_decay/>
        <gravity>0</gravity>
        <velocity_decay/>
        <sensor name='camera1_realsense_depth' type='depth'>
          <update_rate>30</update_rate>
          <camera name='__default__'>
            <horizontal_fov>1.51844</horizontal_fov>
            <image>
              <width>640</width>
              <height>480</height>
              <format>B8G8R8</format>
            </image>
            <clip>
              <near>0.01</near>
              <far>50</far>
            </clip>
          </camera>
          <plugin name='kinect_controller' filename='libgazebo_ros_openni_kinect.so'>
            <baseline>0.2</baseline>
            <alwaysOn>1</alwaysOn>
            <updateRate>30</updateRate>
            <cameraName>camera1</cameraName>
            <imageTopicName>color/image_raw</imageTopicName>
            <cameraInfoTopicName>color/camera_info</cameraInfoTopicName>
            <depthImageTopicName>depth/image_rect_raw</depthImageTopicName>
            <depthImageInfoTopicName>depth/camera_info</depthImageInfoTopicName>
            <pointCloudTopicName>depth/color/points</pointCloudTopicName>
            <frameName>camera1_realsense_gazebo</frameName>
            <pointCloudCutoff>0.105</pointCloudCutoff>
            <pointCloudCutoffMax>8.0</pointCloudCutoffMax>
            <distortionK1>0.00000001</distortionK1>
            <distortionK2>0.00000001</distortionK2>
            <distortionK3>0.00000001</distortionK3>
            <distortionT1>0.00000001</distortionT1>
            <distortionT2>0.00000001</distortionT2>
            <CxPrime>0</CxPrime>
            <Cx>0</Cx>
            <Cy>0</Cy>
            <focalLength>0</focalLength>
            <hackBaseline>0</hackBaseline>
            <robotNamespace>/</robotNamespace>
          </plugin>
          <pose frame=''>0 0.05 0.087 3.14159 -1.57079 1.57079</pose>
        </sensor>
        <enable_wind>0</enable_wind>
        <kinematic>0</kinematic>
      </link>
      <joint name='tm_wrist_3_joint' type='revolute'>
        <child>tm_wrist_3_link</child>
        <parent>tm_wrist_2_link</parent>
        <axis>
          <xyz>0 -1 0</xyz>
          <limit>
            <lower>-4.71239</lower>
            <upper>4.71239</upper>
            <effort>150</effort>
            <velocity>3.15</velocity>
          </limit>
          <dynamics>
            <damping>0</damping>
            <friction>0</friction>
            <spring_reference>0</spring_reference>
            <spring_stiffness>0</spring_stiffness>
          </dynamics>
          <use_parent_model_frame>1</use_parent_model_frame>
        </axis>
      </joint>
      <link name='robotiq_85_left_inner_knuckle_link'>
        <pose frame=''>0.3627 -0.29687 1.2617 -3.14159 -0 -1.5708</pose>
        <inertial>
          <pose frame=''>0 0 0 0 -0 0</pose>
          <mass>0.029951</mass>
          <inertia>
            <ixx>3.9e-05</ixx>
            <ixy>0</ixy>
            <ixz>0</ixz>
            <iyy>5e-06</iyy>
            <iyz>0</iyz>
            <izz>3.5e-05</izz>
          </inertia>
        </inertial>
        <collision name='robotiq_85_left_inner_knuckle_link_collision'>
          <pose frame=''>0 0 0 0 -0 0</pose>
          <geometry>
            <mesh>
              <scale>1 1 1</scale>
              <uri>/home/sis/sis2021_final/catkin_ws/src/marslite/robotiq/robotiq_description/meshes/collision/robotiq_85_inner_knuckle_link.stl</uri>
            </mesh>
          </geometry>
          <max_contacts>10</max_contacts>
          <surface>
            <contact>
              <ode/>
            </contact>
            <bounce/>
            <friction>
              <torsional>
                <ode/>
              </torsional>
              <ode/>
            </friction>
          </surface>
        </collision>
        <visual name='robotiq_85_left_inner_knuckle_link_visual'>
          <pose frame=''>0 0 0 0 -0 0</pose>
          <geometry>
            <mesh>
              <scale>1 1 1</scale>
              <uri>/home/sis/sis2021_final/catkin_ws/src/marslite/robotiq/robotiq_description/meshes/visual/robotiq_85_inner_knuckle_link.dae</uri>
            </mesh>
          </geometry>
        </visual>
        <self_collide>0</self_collide>
        <enable_wind>0</enable_wind>
        <kinematic>0</kinematic>
      </link>
      <joint name='robotiq_85_left_inner_knuckle_joint' type='revolute'>
        <child>robotiq_85_left_inner_knuckle_link</child>
        <parent>tm_wrist_3_link</parent>
        <axis>
          <xyz>0 -0 -1</xyz>
          <limit>
            <lower>-1e+16</lower>
            <upper>1e+16</upper>
          </limit>
          <dynamics>
            <spring_reference>0</spring_reference>
            <spring_stiffness>0</spring_stiffness>
          </dynamics>
          <use_parent_model_frame>1</use_parent_model_frame>
        </axis>
      </joint>
      <link name='robotiq_85_left_finger_tip_link'>
        <pose frame=''>0.400299 -0.33991 1.2617 -3.14159 -0 -1.5708</pose>
        <inertial>
          <pose frame=''>0 0 0 0 -0 0</pose>
          <mass>0.019555</mass>
          <inertia>
            <ixx>2e-06</ixx>
            <ixy>0</ixy>
            <ixz>0</ixz>
            <iyy>5e-06</iyy>
            <iyz>0</iyz>
            <izz>6e-06</izz>
          </inertia>
        </inertial>
        <collision name='robotiq_85_left_finger_tip_link_collision'>
          <pose frame=''>0 0 0 0 -0 0</pose>
          <geometry>
            <mesh>
              <scale>1 1 1</scale>
              <uri>/home/sis/sis2021_final/catkin_ws/src/marslite/robotiq/robotiq_description/meshes/collision/robotiq_85_finger_tip_link.stl</uri>
            </mesh>
          </geometry>
          <surface>
            <contact>
              <ode>
                <kp>1e+06</kp>
                <kd>1</kd>
                <min_depth>0.001</min_depth>
              </ode>
            </contact>
            <friction>
              <ode>
                <mu>1</mu>
                <mu2>1</mu2>
              </ode>
              <torsional>
                <ode/>
              </torsional>
            </friction>
            <bounce/>
          </surface>
          <max_contacts>10</max_contacts>
        </collision>
        <visual name='robotiq_85_left_finger_tip_link_visual'>
          <pose frame=''>0 0 0 0 -0 0</pose>
          <geometry>
            <mesh>
              <scale>1 1 1</scale>
              <uri>/home/sis/sis2021_final/catkin_ws/src/marslite/robotiq/robotiq_description/meshes/visual/robotiq_85_finger_tip_link.dae</uri>
            </mesh>
          </geometry>
          <material>
            <script>
              <uri>__default__</uri>
              <name>__default__</name>
            </script>
          </material>
        </visual>
        <gravity>1</gravity>
        <velocity_decay/>
        <self_collide>0</self_collide>
        <enable_wind>0</enable_wind>
        <kinematic>0</kinematic>
      </link>
      <joint name='robotiq_85_left_finger_tip_joint' type='revolute'>
        <child>robotiq_85_left_finger_tip_link</child>
        <parent>robotiq_85_left_inner_knuckle_link</parent>
        <axis>
          <xyz>0 -0 -1</xyz>
          <limit>
            <lower>-1e+16</lower>
            <upper>1e+16</upper>
          </limit>
          <dynamics>
            <spring_reference>0</spring_reference>
            <spring_stiffness>0</spring_stiffness>
          </dynamics>
          <use_parent_model_frame>1</use_parent_model_frame>
        </axis>
      </joint>
      <link name='robotiq_85_left_knuckle_link'>
        <pose frame=''>0.380601 -0.290355 1.2617 -3.14159 -0 -1.5708</pose>
        <inertial>
          <pose frame=''>-0.002436 -0.018774 0 0 -0 0</pose>
          <mass>0.0458</mass>
          <inertia>
            <ixx>2.29304e-05</ixx>
            <ixy>-4.4183e-06</ixy>
            <ixz>0</ixz>
            <iyy>2.2184e-05</iyy>
            <iyz>0</iyz>
            <izz>4.11145e-05</izz>
          </inertia>
        </inertial>
        <collision name='robotiq_85_left_knuckle_link_collision'>
          <pose frame=''>0 0 0 0 -0 0</pose>
          <geometry>
            <mesh>
              <scale>1 1 1</scale>
              <uri>/home/sis/sis2021_final/catkin_ws/src/marslite/robotiq/robotiq_description/meshes/collision/robotiq_85_knuckle_link.stl</uri>
            </mesh>
          </geometry>
          <max_contacts>10</max_contacts>
          <surface>
            <contact>
              <ode/>
            </contact>
            <bounce/>
            <friction>
              <torsional>
                <ode/>
              </torsional>
              <ode/>
            </friction>
          </surface>
        </collision>
        <collision name='robotiq_85_left_knuckle_link_fixed_joint_lump__robotiq_85_left_finger_link_collision_1'>
          <pose frame=''>-0.004086 -0.031486 0 0 -0 0</pose>
          <geometry>
            <mesh>
              <scale>1 1 1</scale>
              <uri>/home/sis/sis2021_final/catkin_ws/src/marslite/robotiq/robotiq_description/meshes/collision/robotiq_85_finger_link.stl</uri>
            </mesh>
          </geometry>
          <max_contacts>10</max_contacts>
          <surface>
            <contact>
              <ode/>
            </contact>
            <bounce/>
            <friction>
              <torsional>
                <ode/>
              </torsional>
              <ode/>
            </friction>
          </surface>
        </collision>
        <visual name='robotiq_85_left_knuckle_link_visual'>
          <pose frame=''>0 0 0 0 -0 0</pose>
          <geometry>
            <mesh>
              <scale>1 1 1</scale>
              <uri>/home/sis/sis2021_final/catkin_ws/src/marslite/robotiq/robotiq_description/meshes/visual/robotiq_85_knuckle_link.dae</uri>
            </mesh>
          </geometry>
        </visual>
        <visual name='robotiq_85_left_knuckle_link_fixed_joint_lump__robotiq_85_left_finger_link_visual_1'>
          <pose frame=''>-0.004086 -0.031486 0 0 -0 0</pose>
          <geometry>
            <mesh>
              <scale>1 1 1</scale>
              <uri>/home/sis/sis2021_final/catkin_ws/src/marslite/robotiq/robotiq_description/meshes/visual/robotiq_85_finger_link.dae</uri>
            </mesh>
          </geometry>
        </visual>
        <self_collide>0</self_collide>
        <enable_wind>0</enable_wind>
        <kinematic>0</kinematic>
      </link>
      <joint name='robotiq_85_left_knuckle_joint' type='revolute'>
        <child>robotiq_85_left_knuckle_link</child>
        <parent>tm_wrist_3_link</parent>
        <axis>
          <xyz>0 -0 -1</xyz>
          <limit>
            <lower>0</lower>
            <upper>0.80285</upper>
            <effort>1000</effort>
            <velocity>0.5</velocity>
          </limit>
          <dynamics>
            <spring_reference>0</spring_reference>
            <spring_stiffness>0</spring_stiffness>
          </dynamics>
          <use_parent_model_frame>1</use_parent_model_frame>
        </axis>
      </joint>
      <link name='robotiq_85_right_inner_knuckle_link'>
        <pose frame=''>0.3373 -0.29687 1.2617 0 -0 -1.5708</pose>
        <inertial>
          <pose frame=''>0 0 0 0 -0 0</pose>
          <mass>0.029951</mass>
          <inertia>
            <ixx>3.9e-05</ixx>
            <ixy>0</ixy>
            <ixz>0</ixz>
            <iyy>5e-06</iyy>
            <iyz>0</iyz>
            <izz>3.5e-05</izz>
          </inertia>
        </inertial>
        <collision name='robotiq_85_right_inner_knuckle_link_collision'>
          <pose frame=''>0 0 0 0 -0 0</pose>
          <geometry>
            <mesh>
              <scale>1 1 1</scale>
              <uri>/home/sis/sis2021_final/catkin_ws/src/marslite/robotiq/robotiq_description/meshes/collision/robotiq_85_inner_knuckle_link.stl</uri>
            </mesh>
          </geometry>
          <max_contacts>10</max_contacts>
          <surface>
            <contact>
              <ode/>
            </contact>
            <bounce/>
            <friction>
              <torsional>
                <ode/>
              </torsional>
              <ode/>
            </friction>
          </surface>
        </collision>
        <visual name='robotiq_85_right_inner_knuckle_link_visual'>
          <pose frame=''>0 0 0 0 -0 0</pose>
          <geometry>
            <mesh>
              <scale>1 1 1</scale>
              <uri>/home/sis/sis2021_final/catkin_ws/src/marslite/robotiq/robotiq_description/meshes/visual/robotiq_85_inner_knuckle_link.dae</uri>
            </mesh>
          </geometry>
        </visual>
        <self_collide>0</self_collide>
        <enable_wind>0</enable_wind>
        <kinematic>0</kinematic>
      </link>
      <joint name='robotiq_85_right_inner_knuckle_joint' type='revolute'>
        <child>robotiq_85_right_inner_knuckle_link</child>
        <parent>tm_wrist_3_link</parent>
        <axis>
          <xyz>-0 0 1</xyz>
          <limit>
            <lower>-1e+16</lower>
            <upper>1e+16</upper>
          </limit>
          <dynamics>
            <spring_reference>0</spring_reference>
            <spring_stiffness>0</spring_stiffness>
          </dynamics>
          <use_parent_model_frame>1</use_parent_model_frame>
        </axis>
      </joint>
      <link name='robotiq_85_right_finger_tip_link'>
        <pose frame=''>0.299701 -0.33991 1.2617 0 -0 -1.5708</pose>
        <inertial>
          <pose frame=''>0 0 0 0 -0 0</pose>
          <mass>0.019555</mass>
          <inertia>
            <ixx>2e-06</ixx>
            <ixy>0</ixy>
            <ixz>0</ixz>
            <iyy>5e-06</iyy>
            <iyz>0</iyz>
            <izz>6e-06</izz>
          </inertia>
        </inertial>
        <collision name='robotiq_85_right_finger_tip_link_collision'>
          <pose frame=''>0 0 0 0 -0 0</pose>
          <geometry>
            <mesh>
              <scale>1 1 1</scale>
              <uri>/home/sis/sis2021_final/catkin_ws/src/marslite/robotiq/robotiq_description/meshes/collision/robotiq_85_finger_tip_link.stl</uri>
            </mesh>
          </geometry>
          <surface>
            <contact>
              <ode>
                <kp>1e+06</kp>
                <kd>1</kd>
                <min_depth>0.001</min_depth>
              </ode>
            </contact>
            <friction>
              <ode>
                <mu>1</mu>
                <mu2>1</mu2>
              </ode>
              <torsional>
                <ode/>
              </torsional>
            </friction>
            <bounce/>
          </surface>
          <max_contacts>10</max_contacts>
        </collision>
        <visual name='robotiq_85_right_finger_tip_link_visual'>
          <pose frame=''>0 0 0 0 -0 0</pose>
          <geometry>
            <mesh>
              <scale>1 1 1</scale>
              <uri>/home/sis/sis2021_final/catkin_ws/src/marslite/robotiq/robotiq_description/meshes/visual/robotiq_85_finger_tip_link.dae</uri>
            </mesh>
          </geometry>
          <material>
            <script>
              <uri>__default__</uri>
              <name>__default__</name>
            </script>
          </material>
        </visual>
        <gravity>1</gravity>
        <velocity_decay/>
        <self_collide>0</self_collide>
        <enable_wind>0</enable_wind>
        <kinematic>0</kinematic>
      </link>
      <joint name='robotiq_85_right_finger_tip_joint' type='revolute'>
        <child>robotiq_85_right_finger_tip_link</child>
        <parent>robotiq_85_right_inner_knuckle_link</parent>
        <axis>
          <xyz>-0 0 1</xyz>
          <limit>
            <lower>-1e+16</lower>
            <upper>1e+16</upper>
          </limit>
          <dynamics>
            <spring_reference>0</spring_reference>
            <spring_stiffness>0</spring_stiffness>
          </dynamics>
          <use_parent_model_frame>1</use_parent_model_frame>
        </axis>
      </joint>
      <link name='robotiq_85_right_knuckle_link'>
        <pose frame=''>0.319399 -0.290355 1.2617 0 -0 -1.5708</pose>
        <inertial>
          <pose frame=''>-0.002436 -0.018774 0 0 -0 0</pose>
          <mass>0.0458</mass>
          <inertia>
            <ixx>2.29304e-05</ixx>
            <ixy>-4.4183e-06</ixy>
            <ixz>0</ixz>
            <iyy>2.2184e-05</iyy>
            <iyz>0</iyz>
            <izz>4.11145e-05</izz>
          </inertia>
        </inertial>
        <collision name='robotiq_85_right_knuckle_link_collision'>
          <pose frame=''>0 0 0 0 -0 0</pose>
          <geometry>
            <mesh>
              <scale>1 1 1</scale>
              <uri>/home/sis/sis2021_final/catkin_ws/src/marslite/robotiq/robotiq_description/meshes/collision/robotiq_85_knuckle_link.stl</uri>
            </mesh>
          </geometry>
          <max_contacts>10</max_contacts>
          <surface>
            <contact>
              <ode/>
            </contact>
            <bounce/>
            <friction>
              <torsional>
                <ode/>
              </torsional>
              <ode/>
            </friction>
          </surface>
        </collision>
        <collision name='robotiq_85_right_knuckle_link_fixed_joint_lump__robotiq_85_right_finger_link_collision_1'>
          <pose frame=''>-0.004086 -0.031486 0 0 -0 0</pose>
          <geometry>
            <mesh>
              <scale>1 1 1</scale>
              <uri>/home/sis/sis2021_final/catkin_ws/src/marslite/robotiq/robotiq_description/meshes/collision/robotiq_85_finger_link.stl</uri>
            </mesh>
          </geometry>
          <max_contacts>10</max_contacts>
          <surface>
            <contact>
              <ode/>
            </contact>
            <bounce/>
            <friction>
              <torsional>
                <ode/>
              </torsional>
              <ode/>
            </friction>
          </surface>
        </collision>
        <visual name='robotiq_85_right_knuckle_link_visual'>
          <pose frame=''>0 0 0 0 -0 0</pose>
          <geometry>
            <mesh>
              <scale>1 1 1</scale>
              <uri>/home/sis/sis2021_final/catkin_ws/src/marslite/robotiq/robotiq_description/meshes/visual/robotiq_85_knuckle_link.dae</uri>
            </mesh>
          </geometry>
        </visual>
        <visual name='robotiq_85_right_knuckle_link_fixed_joint_lump__robotiq_85_right_finger_link_visual_1'>
          <pose frame=''>-0.004086 -0.031486 0 0 -0 0</pose>
          <geometry>
            <mesh>
              <scale>1 1 1</scale>
              <uri>/home/sis/sis2021_final/catkin_ws/src/marslite/robotiq/robotiq_description/meshes/visual/robotiq_85_finger_link.dae</uri>
            </mesh>
          </geometry>
        </visual>
        <self_collide>0</self_collide>
        <enable_wind>0</enable_wind>
        <kinematic>0</kinematic>
      </link>
      <joint name='robotiq_85_right_knuckle_joint' type='revolute'>
        <child>robotiq_85_right_knuckle_link</child>
        <parent>tm_wrist_3_link</parent>
        <axis>
          <xyz>-0 0 1</xyz>
          <limit>
            <lower>-1e+16</lower>
            <upper>1e+16</upper>
          </limit>
          <dynamics>
            <spring_reference>0</spring_reference>
            <spring_stiffness>0</spring_stiffness>
          </dynamics>
          <use_parent_model_frame>1</use_parent_model_frame>
        </axis>
      </joint>
      <link name='left_wheel'>
        <pose frame=''>0 0.1965 0 0 -0 0</pose>
        <inertial>
          <pose frame=''>0 0 0 0 -0 0</pose>
          <mass>10</mass>
          <inertia>
            <ixx>0.0265564</ixx>
            <ixy>0</ixy>
            <ixz>0</ixz>
            <iyy>0.0265564</iyy>
            <iyz>0</iyz>
            <izz>0.0516128</izz>
          </inertia>
        </inertial>
        <collision name='left_wheel_collision'>
          <pose frame=''>0 0 0 1.5708 -0 0</pose>
          <geometry>
            <cylinder>
              <length>0.03</length>
              <radius>0.1016</radius>
            </cylinder>
          </geometry>
          <surface>
            <contact>
              <ode>
                <kp>1e+06</kp>
                <kd>10000</kd>
              </ode>
            </contact>
            <friction>
              <ode>
                <mu>1.5</mu>
                <mu2>1.5</mu2>
                <fdir1>1 0 0</fdir1>
              </ode>
              <torsional>
                <ode/>
              </torsional>
            </friction>
            <bounce/>
          </surface>
          <max_contacts>10</max_contacts>
        </collision>
        <visual name='left_wheel_visual'>
          <pose frame=''>0 0 0 0 -0 0</pose>
          <geometry>
            <mesh>
              <scale>1 1 1</scale>
              <uri>/home/sis/sis2021_final/catkin_ws/src/marslite/mars_lite_description/meshes/wheel.dae</uri>
            </mesh>
          </geometry>
          <material>
            <script>
              <uri>__default__</uri>
              <name>__default__</name>
            </script>
          </material>
        </visual>
        <gravity>1</gravity>
        <velocity_decay/>
        <self_collide>0</self_collide>
        <enable_wind>0</enable_wind>
        <kinematic>0</kinematic>
      </link>
      <joint name='left_wheel_joint' type='revolute'>
        <child>left_wheel</child>
        <parent>base_link</parent>
        <axis>
          <xyz>0 1 0</xyz>
          <limit>
            <lower>-1e+16</lower>
            <upper>1e+16</upper>
          </limit>
          <dynamics>
            <spring_reference>0</spring_reference>
            <spring_stiffness>0</spring_stiffness>
          </dynamics>
          <use_parent_model_frame>1</use_parent_model_frame>
        </axis>
      </joint>
      <link name='right_wheel'>
        <pose frame=''>0 -0.1965 0 0 -0 0</pose>
        <inertial>
          <pose frame=''>0 0 0 0 -0 0</pose>
          <mass>10</mass>
          <inertia>
            <ixx>0.0265564</ixx>
            <ixy>0</ixy>
            <ixz>0</ixz>
            <iyy>0.0265564</iyy>
            <iyz>0</iyz>
            <izz>0.0516128</izz>
          </inertia>
        </inertial>
        <collision name='right_wheel_collision'>
          <pose frame=''>0 0 0 1.5708 -0 0</pose>
          <geometry>
            <cylinder>
              <length>0.03</length>
              <radius>0.1016</radius>
            </cylinder>
          </geometry>
          <surface>
            <contact>
              <ode>
                <kp>1e+06</kp>
                <kd>10000</kd>
              </ode>
            </contact>
            <friction>
              <ode>
                <mu>1.5</mu>
                <mu2>1.5</mu2>
                <fdir1>1 0 0</fdir1>
              </ode>
              <torsional>
                <ode/>
              </torsional>
            </friction>
            <bounce/>
          </surface>
          <max_contacts>10</max_contacts>
        </collision>
        <visual name='right_wheel_visual'>
          <pose frame=''>0 0 0 0 -0 0</pose>
          <geometry>
            <mesh>
              <scale>1 1 1</scale>
              <uri>/home/sis/sis2021_final/catkin_ws/src/marslite/mars_lite_description/meshes/wheel.dae</uri>
            </mesh>
          </geometry>
          <material>
            <script>
              <uri>__default__</uri>
              <name>__default__</name>
            </script>
          </material>
        </visual>
        <gravity>1</gravity>
        <velocity_decay/>
        <self_collide>0</self_collide>
        <enable_wind>0</enable_wind>
        <kinematic>0</kinematic>
      </link>
      <joint name='right_wheel_joint' type='revolute'>
        <child>right_wheel</child>
        <parent>base_link</parent>
        <axis>
          <xyz>0 1 0</xyz>
          <limit>
            <lower>-1e+16</lower>
            <upper>1e+16</upper>
          </limit>
          <dynamics>
            <spring_reference>0</spring_reference>
            <spring_stiffness>0</spring_stiffness>
          </dynamics>
          <use_parent_model_frame>1</use_parent_model_frame>
        </axis>
      </joint>
      <plugin name='differential_drive_controller' filename='libgazebo_ros_diff_drive.so'>
        <robotNamespace>/</robotNamespace>
        <legacyMode>0</legacyMode>
        <publishWheelTF>0</publishWheelTF>
        <publishWheelJointState>0</publishWheelJointState>
        <odometrySource>encoder</odometrySource>
        <publishOdomTF>1</publishOdomTF>
        <alwaysOn>1</alwaysOn>
        <updateRate>40</updateRate>
        <leftJoint>left_wheel_joint</leftJoint>
        <rightJoint>right_wheel_joint</rightJoint>
        <wheelSeparation>0.393</wheelSeparation>
        <wheelDiameter>0.2032</wheelDiameter>
        <wheelTorque>10.0</wheelTorque>
        <wheelAcceleration>0.5</wheelAcceleration>
        <commandTopic>cmd_vel</commandTopic>
        <odometryTopic>odom_filtered</odometryTopic>
        <odometryFrame>/odom</odometryFrame>
        <robotBaseFrame>/base_link</robotBaseFrame>
        <rosDebugLevel>na</rosDebugLevel>
        <publishTf>1</publishTf>
      </plugin>
      <plugin name='p3d_base_controller' filename='libgazebo_ros_p3d.so'>
        <alwaysOn>1</alwaysOn>
        <updateRate>50.0</updateRate>
        <bodyName>base_link</bodyName>
        <topicName>odom</topicName>
        <gaussianNoise>0.01</gaussianNoise>
        <frameName>world</frameName>
        <xyzOffsets>0 0 0</xyzOffsets>
        <rpyOffsets>0 0 0</rpyOffsets>
        <robotNamespace>/</robotNamespace>
      </plugin>
      <plugin name='ros_control' filename='libgazebo_ros_control.so'>
        <robotNamespace>/</robotNamespace>
      </plugin>
      <static>0</static>
      <plugin name='mimic_robotiq_85_1' filename='libgazebo_mimic_joint_plugin.so'>
        <joint>robotiq_85_left_knuckle_joint</joint>
        <mimicJoint>robotiq_85_right_knuckle_joint</mimicJoint>
        <robotNamespace>/</robotNamespace>
      </plugin>
      <plugin name='mimic_robotiq_85_2' filename='libgazebo_mimic_joint_plugin.so'>
        <joint>robotiq_85_left_knuckle_joint</joint>
        <mimicJoint>robotiq_85_left_inner_knuckle_joint</mimicJoint>
        <robotNamespace>/</robotNamespace>
      </plugin>
      <plugin name='mimic_robotiq_85_3' filename='libgazebo_mimic_joint_plugin.so'>
        <joint>robotiq_85_left_knuckle_joint</joint>
        <mimicJoint>robotiq_85_right_inner_knuckle_joint</mimicJoint>
        <robotNamespace>/</robotNamespace>
      </plugin>
      <plugin name='mimic_robotiq_85_4' filename='libgazebo_mimic_joint_plugin.so'>
        <joint>robotiq_85_left_knuckle_joint</joint>
        <mimicJoint>robotiq_85_left_finger_tip_joint</mimicJoint>
        <multiplier>-1.0</multiplier>
        <offset>0.0</offset>
        <robotNamespace>/</robotNamespace>
      </plugin>
      <plugin name='mimic_robotiq_85_5' filename='libgazebo_mimic_joint_plugin.so'>
        <joint>robotiq_85_left_knuckle_joint</joint>
        <mimicJoint>robotiq_85_right_finger_tip_joint</mimicJoint>
        <multiplier>-1.0</multiplier>
        <offset>0.0</offset>
        <robotNamespace>/</robotNamespace>
      </plugin>
      <pose frame=''>0 0 0 0 -0 0</pose>
    </model>
    <model name='my_store_shelf_01'>
      <link name='link'>
        <inertial>
          <mass>1000</mass>
          <inertia>
            <ixx>840083</ixx>
            <ixy>0</ixy>
            <ixz>0</ixz>
            <iyy>475500</iyy>
            <iyz>0</iyz>
            <izz>1.30208e+06</izz>
          </inertia>
        </inertial>
        <collision name='collision'>
          <geometry>
            <mesh>
              <uri>model://my_store_shelf_01/meshes/my_store_shelf_01.dae</uri>
              <scale>1 1 1</scale>
            </mesh>
          </geometry>
          <surface>
            <friction>
              <ode>
                <mu>0.5</mu>
                <mu2>0.5</mu2>
                <fdir1>0 0 0</fdir1>
                <slip1>0</slip1>
                <slip2>0</slip2>
              </ode>
              <torsional>
                <ode/>
              </torsional>
            </friction>
            <contact>
              <ode/>
            </contact>
            <bounce/>
          </surface>
          <max_contacts>10</max_contacts>
        </collision>
        <visual name='visual'>
          <geometry>
            <mesh>
              <uri>model://my_store_shelf_01/meshes/my_store_shelf_01.dae</uri>
            </mesh>
          </geometry>
          <meta>
            <layer>2</layer>
          </meta>
        </visual>
        <self_collide>0</self_collide>
        <enable_wind>0</enable_wind>
        <kinematic>0</kinematic>
      </link>
      <static>1</static>
      <pose frame=''>0.228923 -0.544596 0 0 -0 0</pose>
    </model>
    <model name='004_sugar_box_textured'>
      <pose frame=''>0.330939 -0.974296 0 0 -0 0</pose>
      <link name='body'>
        <inertial>
          <mass>0.01</mass>
          <pose frame=''>-0.007698 -0.017078 0.086024 0 -0 0</pose>
          <inertia>
            <ixx>0.00315303</ixx>
            <ixy>-1.84651e-05</ixy>
            <ixz>9.37398e-05</ixz>
            <iyy>0.00264458</iyy>
            <iyz>-3.19192e-05</iyz>
            <izz>0.000793799</izz>
          </inertia>
        </inertial>
        <visual name='visual'>
          <geometry>
            <mesh>
              <uri>model://004_sugar_box_textured/textured.dae</uri>
            </mesh>
          </geometry>
        </visual>
        <collision name='collision'>
          <geometry>
            <mesh>
              <uri>model://004_sugar_box_textured/textured.dae</uri>
            </mesh>
          </geometry>
          <max_contacts>10</max_contacts>
          <surface>
            <friction>
              <ode>
                <mu>0.8</mu>
                <mu2>0.8</mu2>
                <slip1>0</slip1>
                <slip2>0</slip2>
              </ode>
              <torsional>
                <ode/>
              </torsional>
            </friction>
            <contact>
              <ode>
                <kp>1e+06</kp>
                <kd>1</kd>
                <max_vel>0</max_vel>
              </ode>
            </contact>
            <bounce/>
          </surface>
        </collision>
        <self_collide>0</self_collide>
        <enable_wind>0</enable_wind>
        <kinematic>0</kinematic>
      </link>
    </model>
    <model name='006_mustard_bottle_textured'>
      <pose frame=''>0.461201 -0.922421 0 0 -0 0</pose>
      <link name='body'>
        <inertial>
          <mass>0.01</mass>
          <pose frame=''>-0.015054 -0.023109 0.075042 0 -0 0</pose>
          <inertia>
            <ixx>0.00243046</ixx>
            <ixy>0.000125786</ixy>
            <ixz>-8.24887e-06</ixz>
            <iyy>0.00267486</iyy>
            <iyz>-1.16901e-05</iyz>
            <izz>0.000701511</izz>
          </inertia>
        </inertial>
        <visual name='visual'>
          <geometry>
            <mesh>
              <uri>model://006_mustard_bottle_textured/textured.dae</uri>
            </mesh>
          </geometry>
        </visual>
        <collision name='collision'>
          <geometry>
            <mesh>
              <uri>model://006_mustard_bottle_textured/textured.dae</uri>
            </mesh>
          </geometry>
          <max_contacts>10</max_contacts>
          <surface>
            <friction>
              <ode>
                <mu>0.8</mu>
                <mu2>0.8</mu2>
                <slip1>0</slip1>
                <slip2>0</slip2>
              </ode>
              <torsional>
                <ode/>
              </torsional>
            </friction>
            <contact>
              <ode>
                <kp>1e+06</kp>
                <kd>1</kd>
                <max_vel>0</max_vel>
              </ode>
            </contact>
            <bounce/>
          </surface>
        </collision>
        <self_collide>0</self_collide>
        <enable_wind>0</enable_wind>
        <kinematic>0</kinematic>
      </link>
    </model>
    <model name='010_potted_meat_can_textured'>
      <pose frame=''>1.14834 -0.725669 0 0 -0 0</pose>
      <link name='body'>
        <inertial>
          <mass>0.01</mass>
          <pose frame=''>-0.03284 -0.026353 0.037831 0 -0 0</pose>
          <inertia>
            <ixx>0.000705389</ixx>
            <ixy>-2.78398e-05</ixy>
            <ixz>-1.55312e-06</ixz>
            <iyy>0.0012091</iyy>
            <iyz>3.13728e-06</iyz>
            <izz>0.000911577</izz>
          </inertia>
        </inertial>
        <visual name='visual'>
          <geometry>
            <mesh>
              <uri>model://010_potted_meat_can_textured/textured.dae</uri>
            </mesh>
          </geometry>
        </visual>
        <collision name='collision'>
          <geometry>
            <mesh>
              <uri>model://010_potted_meat_can_textured/textured.dae</uri>
            </mesh>
          </geometry>
          <max_contacts>10</max_contacts>
          <surface>
            <friction>
              <ode>
                <mu>0.8</mu>
                <mu2>0.8</mu2>
                <slip1>0</slip1>
                <slip2>0</slip2>
              </ode>
              <torsional>
                <ode/>
              </torsional>
            </friction>
            <contact>
              <ode>
                <kp>1e+06</kp>
                <kd>1</kd>
                <max_vel>0</max_vel>
              </ode>
            </contact>
            <bounce/>
          </surface>
        </collision>
        <self_collide>0</self_collide>
        <enable_wind>0</enable_wind>
        <kinematic>0</kinematic>
      </link>
    </model>
    <state world_name='default'>
      <sim_time>617 684000000</sim_time>
      <real_time>636 529943540</real_time>
      <wall_time>1655799900 913734672</wall_time>
      <iterations>617684</iterations>
      <model name='004_sugar_box_textured'>
        <pose frame=''>0.324495 -0.846459 0.821587 -0.003512 -0.001741 0.01003</pose>
        <scale>1 1 1</scale>
        <link name='body'>
          <pose frame=''>0.324495 -0.846459 0.821587 -0.003512 -0.001741 0.01003</pose>
          <velocity>0 0 0 0 -0 0</velocity>
          <acceleration>0.01638 0.011644 -0.037961 -0.134668 0.191915 0.027406</acceleration>
          <wrench>0.000164 0.000116 -0.00038 0 -0 0</wrench>
        </link>
      </model>
      <model name='006_mustard_bottle_textured'>
        <pose frame=''>0.456287 -0.926355 0.824833 0.000115 0.000879 -0.007869</pose>
        <scale>1 1 1</scale>
        <link name='body'>
          <pose frame=''>0.456287 -0.926355 0.824833 0.000115 0.000879 -0.007869</pose>
          <velocity>0 0 0 0 -0 0</velocity>
          <acceleration>0.025635 -0.069585 -0.112337 0.890761 0.322641 0.021392</acceleration>
          <wrench>0.000256 -0.000696 -0.001123 0 -0 0</wrench>
        </link>
      </model>
      <model name='010_potted_meat_can_textured'>
        <pose frame=''>0.206907 -0.894975 0.824829 -0.003424 -0.002319 -0.265903</pose>
        <scale>1 1 1</scale>
        <link name='body'>
          <pose frame=''>0.206907 -0.894975 0.824829 -0.003424 -0.002319 -0.265903</pose>
          <velocity>0 0 0 0 -0 0</velocity>
          <acceleration>0.150721 -0.005917 -0.170683 2.58292 -0.648594 3.12778</acceleration>
          <wrench>0.001507 -5.9e-05 -0.001707 0 -0 0</wrench>
        </link>
      </model>
      <model name='ground_plane'>
        <pose frame=''>0 0 0 0 -0 0</pose>
        <scale>1 1 1</scale>
        <link name='link'>
          <pose frame=''>0 0 0 0 -0 0</pose>
          <velocity>0 0 0 0 -0 0</velocity>
          <acceleration>0 0 0 0 -0 0</acceleration>
          <wrench>0 0 0 0 -0 0</wrench>
        </link>
      </model>
      <model name='mars_lite'>
        <pose frame=''>0.078764 -0.00043 0.101354 0.00021 0.000919 0.000866</pose>
        <scale>1 1 1</scale>
        <link name='base_link'>
          <pose frame=''>0.078764 -0.00043 0.101354 0.00021 0.000919 0.000866</pose>
          <velocity>-0.00333 -0.000328 -0.00503 0.002438 0.013847 0.000597</velocity>
          <acceleration>-0.318199 -0.033873 0.567664 2.53538 0.469367 2.65092</acceleration>
          <wrench>-28.4916 -3.03297 50.8286 0 -0 0</wrench>
        </link>
        <link name='left_wheel'>
          <pose frame=''>0.078594 0.196069 0.101395 0.000288 0.774565 0.001069</pose>
          <velocity>-0.00334 -0.000306 -0.004611 0.002952 0.011454 2.2e-05</velocity>
          <acceleration>-0.442903 -0.085621 0.38495 1.56851 -1.20319 -2.81763</acceleration>
          <wrench>-4.42903 -0.856208 3.8495 0 -0 0</wrench>
        </link>
        <link name='right_wheel'>
          <pose frame=''>0.078934 -0.196931 0.101312 0.000288 0.776013 0.00107</pose>
          <velocity>-0.003377 -0.0003 -0.005371 0.002883 0.018561 -7.4e-05</velocity>
          <acceleration>1.40946 -0.071683 0.96418 1.53667 -1.26572 -2.99781</acceleration>
          <wrench>14.0946 -0.716827 9.6418 0 -0 0</wrench>
        </link>
        <link name='robotiq_85_left_finger_tip_link'>
          <pose frame=''>0.725128 0.077585 1.05996 -3.1389 0.037747 0.499391</pose>
          <velocity>-0.005777 0.016692 -0.034909 -0.348316 -0.015682 0.015459</velocity>
          <acceleration>-5.77682 16.6925 -34.9089 -0.012392 -0.612864 1.7187</acceleration>
          <wrench>-0.112966 0.326422 -0.682644 0 -0 0</wrench>
        </link>
        <link name='robotiq_85_left_inner_knuckle_link'>
          <pose frame=''>0.705374 0.023979 1.06148 -3.1389 0.037746 0.499337</pose>
          <velocity>-0.00586 0.017264 -0.018736 -0.349889 -0.015997 0.015332</velocity>
          <acceleration>-5.85951 17.2644 -18.7365 2.73636 1.00442 -1.91074</acceleration>
          <wrench>-0.175498 0.517085 -0.561176 0 -0 0</wrench>
        </link>
        <link name='robotiq_85_left_knuckle_link'>
          <pose frame=''>0.691085 0.036576 1.06178 -3.13903 0.037883 0.499549</pose>
          <velocity>-0.006037 0.01662 -0.022802 -0.261676 -0.054002 0.015627</velocity>
          <acceleration>10.1213 13.8831 -62.1936 -1.57458 1.37768 2.87489</acceleration>
          <wrench>0.463554 0.635846 -2.84847 0 -0 0</wrench>
        </link>
        <link name='robotiq_85_right_finger_tip_link'>
          <pose frame=''>0.773305 -0.010706 1.05968 0.00259 0.038065 0.499704</pose>
          <velocity>-0.005635 0.01704 -0.004029 -0.252156 -0.083709 0.023316</velocity>
          <acceleration>-5.63513 17.04 -4.0294 -1.33932 -0.935007 0.115878</acceleration>
          <wrench>-0.110195 0.333217 -0.078795 0 -0 0</wrench>
        </link>
        <link name='robotiq_85_right_inner_knuckle_link'>
          <pose frame=''>0.717539 0.001683 1.06142 0.002597 0.038073 0.49976</pose>
          <velocity>-0.00543 0.017247 -0.011381 -0.250941 -0.088457 0.0235</velocity>
          <acceleration>-5.43037 17.247 -11.3807 -0.897684 0.054691 -0.713681</acceleration>
          <wrench>-0.162645 0.516564 -0.340863 0 -0 0</wrench>
        </link>
        <link name='robotiq_85_right_knuckle_link'>
          <pose frame=''>0.720399 -0.017148 1.06162 0.002567 0.037873 0.499649</pose>
          <velocity>-0.005279 0.016588 -0.006149 -0.266079 -0.053376 0.012295</velocity>
          <acceleration>-5.06479 16.6836 -1.08767 2.49573 -0.448371 2.93322</acceleration>
          <wrench>-0.231967 0.764108 -0.049815 0 -0 0</wrench>
        </link>
        <link name='tm_arm_1_link'>
          <pose frame=''>0.498089 -0.128947 0.616023 1.57288 -0.726079 0.489384</pose>
          <velocity>-0.001388 -0.010834 -0.011723 -0.012206 0.001994 -0.038928</velocity>
          <acceleration>-13.4119 -5.70383 -7.12815 -2.48021 -0.923461 2.69333</acceleration>
          <wrench>-147.531 -62.7421 -78.4097 0 -0 0</wrench>
        </link>
        <link name='tm_arm_2_link'>
          <pose frame=''>0.244479 -0.117851 0.862236 1.57637 1.24372 0.496069</pose>
          <velocity>0.002544 0.00605 -0.005498 -0.124938 -0.055399 -0.062698</velocity>
          <acceleration>9.17469 6.6347 2.75454 1.55604 0.701731 0.296337</acceleration>
          <wrench>22.9367 16.5867 6.88636 0 -0 0</wrench>
        </link>
        <link name='tm_base'>
          <pose frame=''>0.429106 -0.000205 0.471032 0.001419 0.001088 0.000872</pose>
          <velocity>0.002257 -0.001063 -0.010497 -0.008115 -0.022159 -0.020993</velocity>
          <acceleration>0.360605 1.89505 0.06303 -3.03772 -1.56554 -1.10636</acceleration>
          <wrench>0.360605 1.89505 0.06303 0 -0 0</wrench>
        </link>
        <link name='tm_shoulder_1_link'>
          <pose frame=''>0.429265 -0.000187 0.616232 1.57235 0.000421 0.490797</pose>
          <velocity>0.014779 -0.001842 -0.0105 -0.007918 -0.000613 -0.039302</velocity>
          <acceleration>23.1259 0.321019 0.108695 -1.33268 -1.26114 -2.36399</acceleration>
          <wrench>104.067 1.44459 0.489128 0 -0 0</wrench>
        </link>
        <link name='tm_wrist_1_link'>
          <pose frame=''>0.554686 -0.072459 0.962137 1.57293 0.0379 0.490688</pose>
          <velocity>0.002852 -0.000888 -0.000878 -0.275599 -0.057574 0.007037</velocity>
          <acceleration>6.7221 -14.3521 9.41512 -1.40301 0.528212 -1.95975</acceleration>
          <wrench>9.74704 -20.8106 13.6519 0 -0 0</wrench>
        </link>
        <link name='tm_wrist_2_link'>
          <pose frame=''>0.55834 -0.070745 1.06806 1.60867 -0.002456 2.0703</pose>
          <velocity>-0.007953 0.018983 -0.001312 -0.273823 -0.05291 0.011619</velocity>
          <acceleration>2.33195 24.4654 8.00285 0.533864 -1.06832 -1.48365</acceleration>
          <wrench>3.38133 35.4749 11.6041 0 -0 0</wrench>
        </link>
        <link name='tm_wrist_3_link'>
          <pose frame=''>0.657582 -0.016572 1.06378 1.60867 -0.002587 2.07028</pose>
          <velocity>-0.005429 0.016923 -0.009896 -0.273565 -0.053204 0.014706</velocity>
          <acceleration>8.73125 15.8636 -24.2664 -1.72137 0.602822 -2.72228</acceleration>
          <wrench>9.05387 16.4498 -25.1631 0 -0 0</wrench>
        </link>
      </model>
      <model name='my_store_shelf_01'>
        <pose frame=''>0.319836 -0.76063 0 0 -0 0</pose>
        <scale>1 1 1</scale>
        <link name='link'>
          <pose frame=''>0.319836 -0.76063 0 0 -0 0</pose>
          <velocity>0 0 0 0 -0 0</velocity>
          <acceleration>0 0 0 0 -0 0</acceleration>
          <wrench>0 0 0 0 -0 0</wrench>
        </link>
      </model>
      <light name='sun'>
        <pose frame=''>0 0 10 0 -0 0</pose>
      </light>
    </state>
    <gui fullscreen='0'>
      <camera name='user_camera'>
        <pose frame=''>1.17212 5.01762 2.90755 0 0.375642 -2.19098</pose>
        <view_controller>orbit</view_controller>
        <projection_type>perspective</projection_type>
      </camera>
    </gui>
  </world>
</sdf>
